2023-12-27 19:20:42,383 (INFO) - django.utils.autoreload - Watching for file changes with StatReloader
2023-12-27 19:21:01,234 (WARNING) - django.request - Not Found: /store/playground/
2023-12-27 19:21:14,919 (WARNING) - django.request - Not Found: /playgournd
2023-12-27 19:21:28,970 (WARNING) - django.request - Not Found: /playground
2023-12-27 19:21:53,472 (WARNING) - django.request - Not Found: /playground/
2023-12-27 19:22:05,285 (INFO) - playground.views - before notify
2023-12-27 19:22:11,382 (CRITICAL) - playground.views - httpbin is offline
2023-12-27 19:22:41,906 (INFO) - django.utils.autoreload - /home/usama/Desktop/githubecommerce/e-commerce/playground/views.py changed, reloading.
2023-12-27 19:22:42,643 (INFO) - django.utils.autoreload - Watching for file changes with StatReloader
2023-12-27 19:22:43,496 (INFO) - playground.views - before notify
2023-12-27 19:22:49,567 (CRITICAL) - playground.views - httpbin is offline
2023-12-27 19:22:54,680 (INFO) - playground.views - before notify
2023-12-27 19:23:00,697 (CRITICAL) - playground.views - httpbin is offline
2023-12-27 19:23:59,228 (INFO) - django.utils.autoreload - /home/usama/Desktop/githubecommerce/e-commerce/playground/views.py changed, reloading.
2023-12-27 19:23:59,965 (INFO) - django.utils.autoreload - Watching for file changes with StatReloader
2023-12-27 19:24:04,670 (INFO) - playground.views - before notify
2023-12-27 19:24:04,670 (INFO) - playground.views - after
2023-12-27 19:24:10,765 (CRITICAL) - playground.views - httpbin is offline
2023-12-27 19:24:21,147 (INFO) - django.utils.autoreload - /home/usama/Desktop/githubecommerce/e-commerce/playground/views.py changed, reloading.
2023-12-27 19:24:21,887 (INFO) - django.utils.autoreload - Watching for file changes with StatReloader
2023-12-27 19:24:23,586 (INFO) - playground.views - before notify
2023-12-27 19:24:29,661 (CRITICAL) - playground.views - httpbin is offline
2023-12-27 19:25:42,794 (INFO) - django.utils.autoreload - /home/usama/Desktop/githubecommerce/e-commerce/playground/views.py changed, reloading.
2023-12-27 19:25:43,452 (INFO) - django.utils.autoreload - Watching for file changes with StatReloader
2023-12-27 19:25:44,658 (INFO) - django.utils.autoreload - /home/usama/Desktop/githubecommerce/e-commerce/playground/views.py changed, reloading.
2023-12-27 19:25:45,268 (INFO) - django.utils.autoreload - Watching for file changes with StatReloader
2023-12-28 07:39:58,695 (INFO) - django.utils.autoreload - /home/usama/Desktop/githubecommerce/e-commerce/manage.py changed, reloading.
2023-12-28 07:44:02,616 (INFO) - django.utils.autoreload - Watching for file changes with StatReloader
2023-12-28 07:44:23,052 (INFO) - django.utils.autoreload - Watching for file changes with StatReloader
2023-12-28 07:45:06,618 (INFO) - django.utils.autoreload - Watching for file changes with StatReloader
2023-12-28 07:48:54,570 (INFO) - django.utils.autoreload - Watching for file changes with StatReloader
2023-12-28 07:50:54,167 (INFO) - django.utils.autoreload - Watching for file changes with StatReloader
2023-12-28 08:03:50,478 (INFO) - django.utils.autoreload - Watching for file changes with StatReloader
2023-12-28 08:08:08,455 (WARNING) - django.request - Unauthorized: /store/collections/
2023-12-28 08:08:08,481 (WARNING) - django.request - Forbidden: /store/collections/
2023-12-28 08:08:08,507 (WARNING) - django.request - Bad Request: /store/collections/
2023-12-28 08:14:40,186 (INFO) - django.utils.autoreload - /home/usama/Desktop/githubecommerce/e-commerce/ecommerce/settings/common.py changed, reloading.
2023-12-28 08:14:40,887 (INFO) - django.utils.autoreload - Watching for file changes with StatReloader
2023-12-28 08:15:02,489 (WARNING) - django.request - Unauthorized: /store/collections/
2023-12-28 08:15:02,555 (WARNING) - django.request - Forbidden: /store/collections/
2023-12-28 08:15:02,616 (WARNING) - django.request - Bad Request: /store/collections/
2023-12-28 08:20:30,916 (WARNING) - django.request - Unauthorized: /store/collections/
2023-12-28 08:20:30,963 (WARNING) - django.request - Forbidden: /store/collections/
2023-12-28 08:20:31,018 (WARNING) - django.request - Bad Request: /store/collections/
2023-12-28 08:24:10,314 (INFO) - django.utils.autoreload - /home/usama/Desktop/githubecommerce/e-commerce/ecommerce/settings/dev.py changed, reloading.
2023-12-28 08:24:11,016 (INFO) - django.utils.autoreload - Watching for file changes with StatReloader
2023-12-28 08:24:11,127 (WARNING) - silk.profiling.profiler - Cannot execute silk_profile as silk is not installed correctly.
2023-12-28 08:24:37,508 (WARNING) - django.request - Unauthorized: /store/collections/
2023-12-28 08:24:37,541 (WARNING) - django.request - Forbidden: /store/collections/
2023-12-28 08:24:37,578 (WARNING) - django.request - Bad Request: /store/collections/
2023-12-28 08:24:53,281 (INFO) - django.utils.autoreload - /home/usama/Desktop/githubecommerce/e-commerce/ecommerce/settings/dev.py changed, reloading.
2023-12-28 08:24:53,951 (INFO) - django.utils.autoreload - Watching for file changes with StatReloader
2023-12-28 08:29:19,123 (INFO) - django.utils.autoreload - /home/usama/Desktop/githubecommerce/e-commerce/ecommerce/settings/common.py changed, reloading.
2023-12-28 08:30:14,021 (INFO) - django.utils.autoreload - Watching for file changes with StatReloader
2023-12-28 08:30:44,870 (WARNING) - django.request - Unauthorized: /store/collections/
2023-12-28 08:30:44,919 (WARNING) - django.request - Forbidden: /store/collections/
2023-12-28 08:30:44,968 (WARNING) - django.request - Bad Request: /store/collections/
2023-12-28 09:18:28,235 (INFO) - django.utils.autoreload - /home/usama/Desktop/githubecommerce/e-commerce/ecommerce/settings/common.py changed, reloading.
2023-12-28 09:18:28,891 (INFO) - django.utils.autoreload - Watching for file changes with StatReloader
2023-12-28 09:18:32,528 (INFO) - django.utils.autoreload - /home/usama/Desktop/githubecommerce/e-commerce/ecommerce/settings/common.py changed, reloading.
2023-12-28 09:18:33,146 (INFO) - django.utils.autoreload - Watching for file changes with StatReloader
2023-12-28 10:40:07,588 (ERROR) - django.request - Internal Server Error: /playground/hello/
Traceback (most recent call last):
  File "/home/usama/.local/share/virtualenvs/e-commerce-vRd7YH7Q/lib/python3.10/site-packages/kombu/utils/functional.py", line 32, in __call__
    return self.__value__
AttributeError: 'ChannelPromise' object has no attribute '__value__'

During handling of the above exception, another exception occurred:

Traceback (most recent call last):
  File "/home/usama/.local/share/virtualenvs/e-commerce-vRd7YH7Q/lib/python3.10/site-packages/kombu/transport/virtual/base.py", line 951, in create_channel
    return self._avail_channels.pop()
IndexError: pop from empty list

During handling of the above exception, another exception occurred:

Traceback (most recent call last):
  File "/home/usama/.local/share/virtualenvs/e-commerce-vRd7YH7Q/lib/python3.10/site-packages/redis/connection.py", line 264, in connect
    sock = self.retry.call_with_retry(
  File "/home/usama/.local/share/virtualenvs/e-commerce-vRd7YH7Q/lib/python3.10/site-packages/redis/retry.py", line 46, in call_with_retry
    return do()
  File "/home/usama/.local/share/virtualenvs/e-commerce-vRd7YH7Q/lib/python3.10/site-packages/redis/connection.py", line 265, in <lambda>
    lambda: self._connect(), lambda error: self.disconnect(error)
  File "/home/usama/.local/share/virtualenvs/e-commerce-vRd7YH7Q/lib/python3.10/site-packages/redis/connection.py", line 627, in _connect
    raise err
  File "/home/usama/.local/share/virtualenvs/e-commerce-vRd7YH7Q/lib/python3.10/site-packages/redis/connection.py", line 615, in _connect
    sock.connect(socket_address)
ConnectionRefusedError: [Errno 111] Connection refused

During handling of the above exception, another exception occurred:

Traceback (most recent call last):
  File "/home/usama/.local/share/virtualenvs/e-commerce-vRd7YH7Q/lib/python3.10/site-packages/kombu/connection.py", line 472, in _reraise_as_library_errors
    yield
  File "/home/usama/.local/share/virtualenvs/e-commerce-vRd7YH7Q/lib/python3.10/site-packages/kombu/connection.py", line 459, in _ensure_connection
    return retry_over_time(
  File "/home/usama/.local/share/virtualenvs/e-commerce-vRd7YH7Q/lib/python3.10/site-packages/kombu/utils/functional.py", line 318, in retry_over_time
    return fun(*args, **kwargs)
  File "/home/usama/.local/share/virtualenvs/e-commerce-vRd7YH7Q/lib/python3.10/site-packages/kombu/connection.py", line 934, in _connection_factory
    self._connection = self._establish_connection()
  File "/home/usama/.local/share/virtualenvs/e-commerce-vRd7YH7Q/lib/python3.10/site-packages/kombu/connection.py", line 860, in _establish_connection
    conn = self.transport.establish_connection()
  File "/home/usama/.local/share/virtualenvs/e-commerce-vRd7YH7Q/lib/python3.10/site-packages/kombu/transport/virtual/base.py", line 975, in establish_connection
    self._avail_channels.append(self.create_channel(self))
  File "/home/usama/.local/share/virtualenvs/e-commerce-vRd7YH7Q/lib/python3.10/site-packages/kombu/transport/virtual/base.py", line 953, in create_channel
    channel = self.Channel(connection)
  File "/home/usama/.local/share/virtualenvs/e-commerce-vRd7YH7Q/lib/python3.10/site-packages/kombu/transport/redis.py", line 743, in __init__
    self.client.ping()
  File "/home/usama/.local/share/virtualenvs/e-commerce-vRd7YH7Q/lib/python3.10/site-packages/redis/commands/core.py", line 1216, in ping
    return self.execute_command("PING", **kwargs)
  File "/home/usama/.local/share/virtualenvs/e-commerce-vRd7YH7Q/lib/python3.10/site-packages/redis/client.py", line 533, in execute_command
    conn = self.connection or pool.get_connection(command_name, **options)
  File "/home/usama/.local/share/virtualenvs/e-commerce-vRd7YH7Q/lib/python3.10/site-packages/redis/connection.py", line 1086, in get_connection
    connection.connect()
  File "/home/usama/.local/share/virtualenvs/e-commerce-vRd7YH7Q/lib/python3.10/site-packages/redis/connection.py", line 270, in connect
    raise ConnectionError(self._error_message(e))
redis.exceptions.ConnectionError: Error 111 connecting to localhost:6379. Connection refused.

The above exception was the direct cause of the following exception:

Traceback (most recent call last):
  File "/home/usama/.local/share/virtualenvs/e-commerce-vRd7YH7Q/lib/python3.10/site-packages/django/core/handlers/exception.py", line 55, in inner
    response = get_response(request)
  File "/home/usama/.local/share/virtualenvs/e-commerce-vRd7YH7Q/lib/python3.10/site-packages/django/core/handlers/base.py", line 197, in _get_response
    response = wrapped_callback(request, *callback_args, **callback_kwargs)
  File "/home/usama/Desktop/githubecommerce/e-commerce/playground/views.py", line 6, in say_hello
    notify_customers.delay('Hello')
  File "/home/usama/.local/share/virtualenvs/e-commerce-vRd7YH7Q/lib/python3.10/site-packages/celery/app/task.py", line 444, in delay
    return self.apply_async(args, kwargs)
  File "/home/usama/.local/share/virtualenvs/e-commerce-vRd7YH7Q/lib/python3.10/site-packages/celery/app/task.py", line 594, in apply_async
    return app.send_task(
  File "/home/usama/.local/share/virtualenvs/e-commerce-vRd7YH7Q/lib/python3.10/site-packages/celery/app/base.py", line 799, in send_task
    amqp.send_task_message(P, name, message, **options)
  File "/home/usama/.local/share/virtualenvs/e-commerce-vRd7YH7Q/lib/python3.10/site-packages/celery/app/amqp.py", line 518, in send_task_message
    ret = producer.publish(
  File "/home/usama/.local/share/virtualenvs/e-commerce-vRd7YH7Q/lib/python3.10/site-packages/kombu/messaging.py", line 186, in publish
    return _publish(
  File "/home/usama/.local/share/virtualenvs/e-commerce-vRd7YH7Q/lib/python3.10/site-packages/kombu/connection.py", line 556, in _ensured
    return fun(*args, **kwargs)
  File "/home/usama/.local/share/virtualenvs/e-commerce-vRd7YH7Q/lib/python3.10/site-packages/kombu/messaging.py", line 195, in _publish
    channel = self.channel
  File "/home/usama/.local/share/virtualenvs/e-commerce-vRd7YH7Q/lib/python3.10/site-packages/kombu/messaging.py", line 218, in _get_channel
    channel = self._channel = channel()
  File "/home/usama/.local/share/virtualenvs/e-commerce-vRd7YH7Q/lib/python3.10/site-packages/kombu/utils/functional.py", line 34, in __call__
    value = self.__value__ = self.__contract__()
  File "/home/usama/.local/share/virtualenvs/e-commerce-vRd7YH7Q/lib/python3.10/site-packages/kombu/messaging.py", line 234, in <lambda>
    channel = ChannelPromise(lambda: connection.default_channel)
  File "/home/usama/.local/share/virtualenvs/e-commerce-vRd7YH7Q/lib/python3.10/site-packages/kombu/connection.py", line 953, in default_channel
    self._ensure_connection(**conn_opts)
  File "/home/usama/.local/share/virtualenvs/e-commerce-vRd7YH7Q/lib/python3.10/site-packages/kombu/connection.py", line 458, in _ensure_connection
    with ctx():
  File "/usr/lib/python3.10/contextlib.py", line 153, in __exit__
    self.gen.throw(typ, value, traceback)
  File "/home/usama/.local/share/virtualenvs/e-commerce-vRd7YH7Q/lib/python3.10/site-packages/kombu/connection.py", line 476, in _reraise_as_library_errors
    raise ConnectionError(str(exc)) from exc
kombu.exceptions.OperationalError: Error 111 connecting to localhost:6379. Connection refused.
2023-12-28 10:40:42,878 (ERROR) - django.request - Internal Server Error: /playground/hello/
Traceback (most recent call last):
  File "/home/usama/.local/share/virtualenvs/e-commerce-vRd7YH7Q/lib/python3.10/site-packages/kombu/utils/functional.py", line 32, in __call__
    return self.__value__
AttributeError: 'ChannelPromise' object has no attribute '__value__'

During handling of the above exception, another exception occurred:

Traceback (most recent call last):
  File "/home/usama/.local/share/virtualenvs/e-commerce-vRd7YH7Q/lib/python3.10/site-packages/kombu/transport/virtual/base.py", line 951, in create_channel
    return self._avail_channels.pop()
IndexError: pop from empty list

During handling of the above exception, another exception occurred:

Traceback (most recent call last):
  File "/home/usama/.local/share/virtualenvs/e-commerce-vRd7YH7Q/lib/python3.10/site-packages/redis/connection.py", line 264, in connect
    sock = self.retry.call_with_retry(
  File "/home/usama/.local/share/virtualenvs/e-commerce-vRd7YH7Q/lib/python3.10/site-packages/redis/retry.py", line 46, in call_with_retry
    return do()
  File "/home/usama/.local/share/virtualenvs/e-commerce-vRd7YH7Q/lib/python3.10/site-packages/redis/connection.py", line 265, in <lambda>
    lambda: self._connect(), lambda error: self.disconnect(error)
  File "/home/usama/.local/share/virtualenvs/e-commerce-vRd7YH7Q/lib/python3.10/site-packages/redis/connection.py", line 627, in _connect
    raise err
  File "/home/usama/.local/share/virtualenvs/e-commerce-vRd7YH7Q/lib/python3.10/site-packages/redis/connection.py", line 615, in _connect
    sock.connect(socket_address)
ConnectionRefusedError: [Errno 111] Connection refused

During handling of the above exception, another exception occurred:

Traceback (most recent call last):
  File "/home/usama/.local/share/virtualenvs/e-commerce-vRd7YH7Q/lib/python3.10/site-packages/kombu/connection.py", line 472, in _reraise_as_library_errors
    yield
  File "/home/usama/.local/share/virtualenvs/e-commerce-vRd7YH7Q/lib/python3.10/site-packages/kombu/connection.py", line 459, in _ensure_connection
    return retry_over_time(
  File "/home/usama/.local/share/virtualenvs/e-commerce-vRd7YH7Q/lib/python3.10/site-packages/kombu/utils/functional.py", line 318, in retry_over_time
    return fun(*args, **kwargs)
  File "/home/usama/.local/share/virtualenvs/e-commerce-vRd7YH7Q/lib/python3.10/site-packages/kombu/connection.py", line 934, in _connection_factory
    self._connection = self._establish_connection()
  File "/home/usama/.local/share/virtualenvs/e-commerce-vRd7YH7Q/lib/python3.10/site-packages/kombu/connection.py", line 860, in _establish_connection
    conn = self.transport.establish_connection()
  File "/home/usama/.local/share/virtualenvs/e-commerce-vRd7YH7Q/lib/python3.10/site-packages/kombu/transport/virtual/base.py", line 975, in establish_connection
    self._avail_channels.append(self.create_channel(self))
  File "/home/usama/.local/share/virtualenvs/e-commerce-vRd7YH7Q/lib/python3.10/site-packages/kombu/transport/virtual/base.py", line 953, in create_channel
    channel = self.Channel(connection)
  File "/home/usama/.local/share/virtualenvs/e-commerce-vRd7YH7Q/lib/python3.10/site-packages/kombu/transport/redis.py", line 743, in __init__
    self.client.ping()
  File "/home/usama/.local/share/virtualenvs/e-commerce-vRd7YH7Q/lib/python3.10/site-packages/redis/commands/core.py", line 1216, in ping
    return self.execute_command("PING", **kwargs)
  File "/home/usama/.local/share/virtualenvs/e-commerce-vRd7YH7Q/lib/python3.10/site-packages/redis/client.py", line 533, in execute_command
    conn = self.connection or pool.get_connection(command_name, **options)
  File "/home/usama/.local/share/virtualenvs/e-commerce-vRd7YH7Q/lib/python3.10/site-packages/redis/connection.py", line 1086, in get_connection
    connection.connect()
  File "/home/usama/.local/share/virtualenvs/e-commerce-vRd7YH7Q/lib/python3.10/site-packages/redis/connection.py", line 270, in connect
    raise ConnectionError(self._error_message(e))
redis.exceptions.ConnectionError: Error 111 connecting to localhost:6379. Connection refused.

The above exception was the direct cause of the following exception:

Traceback (most recent call last):
  File "/home/usama/.local/share/virtualenvs/e-commerce-vRd7YH7Q/lib/python3.10/site-packages/django/core/handlers/exception.py", line 55, in inner
    response = get_response(request)
  File "/home/usama/.local/share/virtualenvs/e-commerce-vRd7YH7Q/lib/python3.10/site-packages/django/core/handlers/base.py", line 197, in _get_response
    response = wrapped_callback(request, *callback_args, **callback_kwargs)
  File "/home/usama/Desktop/githubecommerce/e-commerce/playground/views.py", line 6, in say_hello
    notify_customers.delay('Hello')
  File "/home/usama/.local/share/virtualenvs/e-commerce-vRd7YH7Q/lib/python3.10/site-packages/celery/app/task.py", line 444, in delay
    return self.apply_async(args, kwargs)
  File "/home/usama/.local/share/virtualenvs/e-commerce-vRd7YH7Q/lib/python3.10/site-packages/celery/app/task.py", line 594, in apply_async
    return app.send_task(
  File "/home/usama/.local/share/virtualenvs/e-commerce-vRd7YH7Q/lib/python3.10/site-packages/celery/app/base.py", line 799, in send_task
    amqp.send_task_message(P, name, message, **options)
  File "/home/usama/.local/share/virtualenvs/e-commerce-vRd7YH7Q/lib/python3.10/site-packages/celery/app/amqp.py", line 518, in send_task_message
    ret = producer.publish(
  File "/home/usama/.local/share/virtualenvs/e-commerce-vRd7YH7Q/lib/python3.10/site-packages/kombu/messaging.py", line 186, in publish
    return _publish(
  File "/home/usama/.local/share/virtualenvs/e-commerce-vRd7YH7Q/lib/python3.10/site-packages/kombu/connection.py", line 556, in _ensured
    return fun(*args, **kwargs)
  File "/home/usama/.local/share/virtualenvs/e-commerce-vRd7YH7Q/lib/python3.10/site-packages/kombu/messaging.py", line 195, in _publish
    channel = self.channel
  File "/home/usama/.local/share/virtualenvs/e-commerce-vRd7YH7Q/lib/python3.10/site-packages/kombu/messaging.py", line 218, in _get_channel
    channel = self._channel = channel()
  File "/home/usama/.local/share/virtualenvs/e-commerce-vRd7YH7Q/lib/python3.10/site-packages/kombu/utils/functional.py", line 34, in __call__
    value = self.__value__ = self.__contract__()
  File "/home/usama/.local/share/virtualenvs/e-commerce-vRd7YH7Q/lib/python3.10/site-packages/kombu/messaging.py", line 234, in <lambda>
    channel = ChannelPromise(lambda: connection.default_channel)
  File "/home/usama/.local/share/virtualenvs/e-commerce-vRd7YH7Q/lib/python3.10/site-packages/kombu/connection.py", line 953, in default_channel
    self._ensure_connection(**conn_opts)
  File "/home/usama/.local/share/virtualenvs/e-commerce-vRd7YH7Q/lib/python3.10/site-packages/kombu/connection.py", line 458, in _ensure_connection
    with ctx():
  File "/usr/lib/python3.10/contextlib.py", line 153, in __exit__
    self.gen.throw(typ, value, traceback)
  File "/home/usama/.local/share/virtualenvs/e-commerce-vRd7YH7Q/lib/python3.10/site-packages/kombu/connection.py", line 476, in _reraise_as_library_errors
    raise ConnectionError(str(exc)) from exc
kombu.exceptions.OperationalError: Error 111 connecting to localhost:6379. Connection refused.
2024-01-02 14:32:17,599 (WARNING) - django.request - Not Found: /favicon.ico
2024-01-02 14:46:00,842 (ERROR) - django.security.DisallowedHost - Invalid HTTP_HOST header: '0.0.0.0:8000'. You may need to add '0.0.0.0' to ALLOWED_HOSTS.
Traceback (most recent call last):
  File "/home/usama/.local/share/virtualenvs/e-commerce-vRd7YH7Q/lib/python3.10/site-packages/django/core/handlers/exception.py", line 55, in inner
    response = get_response(request)
  File "/home/usama/.local/share/virtualenvs/e-commerce-vRd7YH7Q/lib/python3.10/site-packages/django/utils/deprecation.py", line 133, in __call__
    response = self.process_request(request)
  File "/home/usama/.local/share/virtualenvs/e-commerce-vRd7YH7Q/lib/python3.10/site-packages/django/middleware/common.py", line 48, in process_request
    host = request.get_host()
  File "/home/usama/.local/share/virtualenvs/e-commerce-vRd7YH7Q/lib/python3.10/site-packages/django/http/request.py", line 151, in get_host
    raise DisallowedHost(msg)
django.core.exceptions.DisallowedHost: Invalid HTTP_HOST header: '0.0.0.0:8000'. You may need to add '0.0.0.0' to ALLOWED_HOSTS.
2024-01-02 14:46:00,893 (WARNING) - django.request - Bad Request: /
2024-01-02 14:46:03,382 (ERROR) - django.security.DisallowedHost - Invalid HTTP_HOST header: '0.0.0.0:8000'. You may need to add '0.0.0.0' to ALLOWED_HOSTS.
Traceback (most recent call last):
  File "/home/usama/.local/share/virtualenvs/e-commerce-vRd7YH7Q/lib/python3.10/site-packages/django/core/handlers/exception.py", line 55, in inner
    response = get_response(request)
  File "/home/usama/.local/share/virtualenvs/e-commerce-vRd7YH7Q/lib/python3.10/site-packages/django/utils/deprecation.py", line 133, in __call__
    response = self.process_request(request)
  File "/home/usama/.local/share/virtualenvs/e-commerce-vRd7YH7Q/lib/python3.10/site-packages/django/middleware/common.py", line 48, in process_request
    host = request.get_host()
  File "/home/usama/.local/share/virtualenvs/e-commerce-vRd7YH7Q/lib/python3.10/site-packages/django/http/request.py", line 151, in get_host
    raise DisallowedHost(msg)
django.core.exceptions.DisallowedHost: Invalid HTTP_HOST header: '0.0.0.0:8000'. You may need to add '0.0.0.0' to ALLOWED_HOSTS.
2024-01-02 14:46:03,522 (WARNING) - django.request - Bad Request: /favicon.ico
2024-01-02 14:46:46,010 (ERROR) - django.security.DisallowedHost - Invalid HTTP_HOST header: '0.0.0.0:8000'. You may need to add '0.0.0.0' to ALLOWED_HOSTS.
Traceback (most recent call last):
  File "/home/usama/.local/share/virtualenvs/e-commerce-vRd7YH7Q/lib/python3.10/site-packages/django/core/handlers/exception.py", line 55, in inner
    response = get_response(request)
  File "/home/usama/.local/share/virtualenvs/e-commerce-vRd7YH7Q/lib/python3.10/site-packages/django/utils/deprecation.py", line 133, in __call__
    response = self.process_request(request)
  File "/home/usama/.local/share/virtualenvs/e-commerce-vRd7YH7Q/lib/python3.10/site-packages/django/middleware/common.py", line 48, in process_request
    host = request.get_host()
  File "/home/usama/.local/share/virtualenvs/e-commerce-vRd7YH7Q/lib/python3.10/site-packages/django/http/request.py", line 151, in get_host
    raise DisallowedHost(msg)
django.core.exceptions.DisallowedHost: Invalid HTTP_HOST header: '0.0.0.0:8000'. You may need to add '0.0.0.0' to ALLOWED_HOSTS.
2024-01-02 14:46:46,032 (WARNING) - django.request - Bad Request: /
2024-01-02 14:46:46,473 (ERROR) - django.security.DisallowedHost - Invalid HTTP_HOST header: '0.0.0.0:8000'. You may need to add '0.0.0.0' to ALLOWED_HOSTS.
Traceback (most recent call last):
  File "/home/usama/.local/share/virtualenvs/e-commerce-vRd7YH7Q/lib/python3.10/site-packages/django/core/handlers/exception.py", line 55, in inner
    response = get_response(request)
  File "/home/usama/.local/share/virtualenvs/e-commerce-vRd7YH7Q/lib/python3.10/site-packages/django/utils/deprecation.py", line 133, in __call__
    response = self.process_request(request)
  File "/home/usama/.local/share/virtualenvs/e-commerce-vRd7YH7Q/lib/python3.10/site-packages/django/middleware/common.py", line 48, in process_request
    host = request.get_host()
  File "/home/usama/.local/share/virtualenvs/e-commerce-vRd7YH7Q/lib/python3.10/site-packages/django/http/request.py", line 151, in get_host
    raise DisallowedHost(msg)
django.core.exceptions.DisallowedHost: Invalid HTTP_HOST header: '0.0.0.0:8000'. You may need to add '0.0.0.0' to ALLOWED_HOSTS.
2024-01-02 14:46:46,500 (WARNING) - django.request - Bad Request: /favicon.ico
2024-01-02 14:47:00,944 (ERROR) - django.security.DisallowedHost - Invalid HTTP_HOST header: '0.0.0.0:8000'. You may need to add '0.0.0.0' to ALLOWED_HOSTS.
Traceback (most recent call last):
  File "/home/usama/.local/share/virtualenvs/e-commerce-vRd7YH7Q/lib/python3.10/site-packages/django/core/handlers/exception.py", line 55, in inner
    response = get_response(request)
  File "/home/usama/.local/share/virtualenvs/e-commerce-vRd7YH7Q/lib/python3.10/site-packages/django/utils/deprecation.py", line 133, in __call__
    response = self.process_request(request)
  File "/home/usama/.local/share/virtualenvs/e-commerce-vRd7YH7Q/lib/python3.10/site-packages/django/middleware/common.py", line 48, in process_request
    host = request.get_host()
  File "/home/usama/.local/share/virtualenvs/e-commerce-vRd7YH7Q/lib/python3.10/site-packages/django/http/request.py", line 151, in get_host
    raise DisallowedHost(msg)
django.core.exceptions.DisallowedHost: Invalid HTTP_HOST header: '0.0.0.0:8000'. You may need to add '0.0.0.0' to ALLOWED_HOSTS.
2024-01-02 14:47:01,181 (WARNING) - django.request - Bad Request: /
2024-01-02 14:47:01,449 (ERROR) - django.security.DisallowedHost - Invalid HTTP_HOST header: '0.0.0.0:8000'. You may need to add '0.0.0.0' to ALLOWED_HOSTS.
Traceback (most recent call last):
  File "/home/usama/.local/share/virtualenvs/e-commerce-vRd7YH7Q/lib/python3.10/site-packages/django/core/handlers/exception.py", line 55, in inner
    response = get_response(request)
  File "/home/usama/.local/share/virtualenvs/e-commerce-vRd7YH7Q/lib/python3.10/site-packages/django/utils/deprecation.py", line 133, in __call__
    response = self.process_request(request)
  File "/home/usama/.local/share/virtualenvs/e-commerce-vRd7YH7Q/lib/python3.10/site-packages/django/middleware/common.py", line 48, in process_request
    host = request.get_host()
  File "/home/usama/.local/share/virtualenvs/e-commerce-vRd7YH7Q/lib/python3.10/site-packages/django/http/request.py", line 151, in get_host
    raise DisallowedHost(msg)
django.core.exceptions.DisallowedHost: Invalid HTTP_HOST header: '0.0.0.0:8000'. You may need to add '0.0.0.0' to ALLOWED_HOSTS.
2024-01-02 14:47:01,477 (WARNING) - django.request - Bad Request: /favicon.ico
2024-01-02 14:48:24,144 (WARNING) - django.request - Not Found: /favicon.ico
